#VRML_SIM R2025a utf8

EXTERNPROTO "https://raw.githubusercontent.com/cyberbotics/webots/R2025a/projects/objects/backgrounds/protos/TexturedBackground.proto"
EXTERNPROTO "https://raw.githubusercontent.com/cyberbotics/webots/R2025a/projects/objects/backgrounds/protos/TexturedBackgroundLight.proto"
EXTERNPROTO "https://raw.githubusercontent.com/cyberbotics/webots/R2025a/projects/objects/floors/protos/RectangleArena.proto"

WorldInfo {
}
Viewpoint {
  orientation 0.0137 -0.0199 0.9997 1.208
  position -4.78 -36.7 5.48
}
TexturedBackground {
}
TexturedBackgroundLight {
}
RectangleArena {
  translation 0.21 0 0
  floorSize 7 8
}
DEF ROBOT1 Robot {
  translation 0 0 0
  children [
    DEF BASE Solid {
      children [
        Transform {
          rotation 1 0 0 1.57079632679
          children [
            CadShape {
              url [
                "/home/andres/programacion/brazo_robotico/brazo-robotico/base.obj"
              ]
            }
          ]
        }
      ]
      name "base"
    }
    HingeJoint {
      jointParameters HingeJointParameters {
        axis 0 0 1
        anchor 0.024 -0.303 1.342
      }
      device [
        RotationalMotor {
          name "motor_base"
          minPosition -3.14159
          maxPosition 3.14159
        }
        PositionSensor {
          name "sensor_base"
        }
      ]
      endPoint DEF BRAZO1 Solid {
        translation 0 0 0.708
        children [
          Transform {
            rotation 1 0 0 1.57079632679
            children [
              CadShape {
                url [
                  "/home/andres/programacion/brazo_robotico/brazo-robotico/brazo-1.obj"
                ]
              }
            ]
          }
          HingeJoint {
            jointParameters HingeJointParameters {
              axis 1 0 0
              anchor 0.025 -0.284 5.498
            }
            device [
              RotationalMotor {
                name "motor_brazo_1"
                minPosition -1.5708
                maxPosition 1.5708
              }
              PositionSensor {
                name "sensor_brazo_1"
              }
            ]
            endPoint DEF BRAZO2 Solid {
              translation 0 0 4.864
              children [
                Transform {
                  rotation 1 0 0 1.57079632679
                  children [
                    CadShape {
                      url [
                        "/home/andres/programacion/brazo_robotico/brazo-robotico/brazo-1.obj"
                      ]
                    }
                  ]
                }
                HingeJoint {
                  jointParameters HingeJointParameters {
                    axis 1 0 0
                    anchor 0.025 -0.284 5.498
                  }
                  device [
                    RotationalMotor {
                      name "motor_brazo_2"
                      minPosition -1.5708
                      maxPosition 1.5708
                    }
                    PositionSensor {
                      name "sensor_brazo_2"
                    }
                  ]
                  endPoint DEF BRAZO3 Solid {
                    translation 0 0 4.864
                    children [
                      Transform {
                        rotation 1 0 0 1.57079632679
                        children [
                          CadShape {
                            url [
                              "/home/andres/programacion/brazo_robotico/brazo-robotico/brazo-1.obj"
                            ]
                          }
                        ]
                      }
                      HingeJoint {
                        jointParameters HingeJointParameters {
                          axis 1 0 0
                          anchor 0.025 -0.284 5.498
                        }
                        device [
                          RotationalMotor {
                            name "motor_brazo_3"
                            minPosition -1.5708
                            maxPosition 1.5708
                          }
                          PositionSensor {
                            name "sensor_brazo_3"
                          }
                        ]
                        endPoint DEF GARRA Solid {
                          translation 0 0 4.864
                          children [
                            Transform {
                              rotation 1 0 0 1.57079632679
                              children [
                                CadShape {
                                  url [
                                    "/home/andres/programacion/brazo_robotico/brazo-robotico/garra.obj"
                                  ]
                                }
                              ]
                            }
                            HingeJoint {
                              jointParameters HingeJointParameters {
                                axis 0 1 0
                                anchor -0.442 -0.264 3.249
                              }
                              device [
                                RotationalMotor {
                                  name "motor_garra_izq"
                                  minPosition -0.8
                                  maxPosition 0
                                }
                                PositionSensor {
                                  name "sensor_garra_izq"
                                }
                              ]
                              endPoint Solid {
                                translation -0.442 -0.264 3.249
                                name "dedo_izq"
                              }
                            }
                            HingeJoint {
                              jointParameters HingeJointParameters {
                                axis 0 -1 0
                                anchor 0.467 -0.264 3.249
                              }
                              device [
                                RotationalMotor {
                                  name "motor_garra_der"
                                  minPosition -0.8
                                  maxPosition 0
                                }
                                PositionSensor {
                                  name "sensor_garra_der"
                                }
                              ]
                              endPoint Solid {
                                translation 0.467 -0.264 3.249
                                name "dedo_der"
                              }
                            }
                          ]
                          name "garra"
                        }
                      }
                    ]
                    name "brazo_3"
                  }
                }
              ]
              name "brazo_2"
            }
          }
        ]
        name "brazo_1"
      }
    }
  ]
  name "robot_brazo_1"
  controller "robot_brazo"
}
