#VRML_SIM R2025a utf8

EXTERNPROTO "https://raw.githubusercontent.com/cyberbotics/webots/R2025a/projects/objects/backgrounds/protos/TexturedBackground.proto"
EXTERNPROTO "https://raw.githubusercontent.com/cyberbotics/webots/R2025a/projects/objects/backgrounds/protos/TexturedBackgroundLight.proto"
EXTERNPROTO "https://raw.githubusercontent.com/cyberbotics/webots/R2025a/projects/objects/floors/protos/RectangleArena.proto"

WorldInfo {
}
Viewpoint {
  orientation 0.01370011103984997 -0.019900161291460904 0.9997081026670084 1.208
  position -4.78 -36.7 5.48
}
TexturedBackground {
}
TexturedBackgroundLight {
}
RectangleArena {
  translation 0.21 0 0
  floorSize 26 26
}
DEF ROBOT1 Robot {
  children [
    DEF BASE Solid {
      children [
        Pose {
          rotation 1 0 0 1.57079632679
          children [
            CadShape {
              url [
                "/home/andres/programacion/brazo_robotico/brazo-robotico/base.obj"
              ]
            }
          ]
        }
      ]
      name "base"
    }
    HingeJoint {
      jointParameters HingeJointParameters {
        position -2.5779199999999913
        axis 0 0 1
        anchor 0.024 -0.303 1.342
      }
      device [
        RotationalMotor {
          name "motor_base"
          minPosition -3.14159
          maxPosition 3.14159
        }
        PositionSensor {
          name "sensor_base"
        }
      ]
      endPoint DEF BRAZO1 Solid {
        translation 0.2061783326819202 -0.5463023943598493 0.7080000000000001
        rotation 0 0 -0.9999999999999999 2.5779199999999913
        children [
          Pose {
            rotation 1 0 0 1.57079632679
            children [
              CadShape {
                url [
                  "/home/andres/programacion/brazo_robotico/brazo-robotico/brazo-1.obj"
                ]
              }
            ]
          }
          HingeJoint {
            jointParameters HingeJointParameters {
              position 1.0950400000000031
              anchor 0.025 -0.284 5.498
            }
            device [
              RotationalMotor {
                name "motor_brazo_1"
                minPosition -1.5708
                maxPosition 1.5708
              }
              PositionSensor {
                name "sensor_brazo_1"
              }
            ]
            endPoint DEF BRAZO2 Solid {
              translation 6.938893903907228e-18 0.40966722444059517 5.46008190752581
              rotation 1 0 0 1.0950400000000031
              children [
                Pose {
                  rotation 1 0 0 1.57079632679
                  children [
                    CadShape {
                      url [
                        "/home/andres/programacion/brazo_robotico/brazo-robotico/brazo-1.obj"
                      ]
                    }
                  ]
                }
                HingeJoint {
                  jointParameters HingeJointParameters {
                    position 1.3056000000000043
                    anchor 0.025 -0.284 5.498
                  }
                  device [
                    RotationalMotor {
                      name "motor_brazo_2"
                      minPosition -1.5708
                      maxPosition 1.5708
                    }
                    PositionSensor {
                      name "sensor_brazo_2"
                    }
                  ]
                  endPoint DEF BRAZO3 Solid {
                    translation 3.469446951953614e-18 0.40227207480881083 5.605901062726974
                    rotation 1 0 0 1.3056000000000043
                    children [
                      Pose {
                        rotation 1 0 0 1.57079632679
                        children [
                          CadShape {
                            url [
                              "/home/andres/programacion/brazo_robotico/brazo-robotico/brazo-1.obj"
                            ]
                          }
                        ]
                      }
                      HingeJoint {
                        jointParameters HingeJointParameters {
                          position 0.2304
                          anchor 0.025 -0.284 5.498
                        }
                        device [
                          RotationalMotor {
                            name "motor_brazo_3"
                            minPosition -1.5708
                            maxPosition 1.5708
                          }
                          PositionSensor {
                            name "sensor_brazo_3"
                          }
                        ]
                        endPoint DEF GARRA Solid {
                          translation 6.938893903907228e-18 0.1372799959633217 4.9456095900532455
                          rotation 1 0 0 0.23040000000000038
                          children [
                            Pose {
                              rotation 1 0 0 1.57079632679
                              children [
                                CadShape {
                                  url [
                                    "/home/andres/programacion/brazo_robotico/brazo-robotico/garra.obj"
                                  ]
                                }
                              ]
                            }
                            Connector {
                              translation 0 -0.264 3.0
                              name "conector_garra"
                              type "symmetric"
                              distanceTolerance 50.0
                              axisTolerance 3.14159
                              boundingObject Sphere { radius 0.001 }
                            }
                            HingeJoint {
                              jointParameters HingeJointParameters {
                                axis 0 1 0
                                anchor -0.442 -0.264 3.249
                              }
                              device [
                                RotationalMotor {
                                  name "motor_garra_izq"
                                }
                                PositionSensor {
                                  name "sensor_garra_izq"
                                }
                              ]
                              endPoint Solid {
                                translation -0.442 -0.264 3.249
                                name "dedo_izq"
                                boundingObject Pose {
                                  translation 0 0 1.3
                                  children [
                                    Shape {
                                      geometry Box {
                                        size 0.2 0.2 2.6
                                      }
                                    }
                                  ]
                                }
                              }
                            }
                            HingeJoint {
                              jointParameters HingeJointParameters {
                                axis 0 -1 0
                                anchor 0.467 -0.264 3.249
                              }
                              device [
                                RotationalMotor {
                                  name "motor_garra_der"
                                }
                                PositionSensor {
                                  name "sensor_garra_der"
                                }
                              ]
                              endPoint Solid {
                                translation 0.467 -0.264 3.249
                                name "dedo_der"
                                boundingObject Pose {
                                  translation 0 0 1.3
                                  children [
                                    Shape {
                                      geometry Box {
                                        size 0.2 0.2 2.6
                                      }
                                    }
                                  ]
                                }
                              }
                            }
                          ]
                          name "garra"
                        }
                      }
                    ]
                    name "brazo_3"
                  }
                }
              ]
              name "brazo_2"
            }
          }
        ]
        name "brazo_1"
      }
    }
  ]
  name "robot_brazo_1"
  controller "robot_brazo"
}

Robot {
  controller "<none>"
  translation 0 5 1
  children [
    Connector {
      name "conector_caja"
      type "symmetric"
      distanceTolerance 50.0
      axisTolerance 3.14159
      boundingObject Sphere { radius 0.001 }
    }
    Shape {
      appearance PBRAppearance {
        baseColor 0.8 0.2 0.2
        roughness 0.5
        metalness 0
      }
      geometry Box {
        size 0.6 0.6 0.6
      }
    }
  ]
  name "caja_roja"
  boundingObject Box {
    size 0.6 0.6 0.6
  }
  physics Physics {
    density -1
    mass 0.001
  }
}
