#VRML_SIM R2025a utf8

EXTERNPROTO "https://raw.githubusercontent.com/cyberbotics/webots/R2025a/projects/objects/backgrounds/protos/TexturedBackground.proto"
EXTERNPROTO "https://raw.githubusercontent.com/cyberbotics/webots/R2025a/projects/objects/backgrounds/protos/TexturedBackgroundLight.proto"
EXTERNPROTO "https://raw.githubusercontent.com/cyberbotics/webots/R2025a/projects/objects/floors/protos/RectangleArena.proto"

WorldInfo {
}
Viewpoint {
  orientation -0.058560569668644216 -0.07276257792220849 0.9956285788054692 4.92356094900595
  position 1.1860306214203136 27.655237178032813 9.646078619853283
}
TexturedBackground {
}
TexturedBackgroundLight {
}
RectangleArena {
  translation 0.21 0 0
  floorSize 7 8
}
DEF ROBOT1 Robot {
  translation 0.7 1.3 1.96
  children [
    DEF BASE Solid {
      rotation 1 0 0 1.5708
      children [
        CadShape {
          url [
            "/home/andres/programacion/brazo_robotico/worlds/base.obj"
          ]
        }
      ]
      name "base"
    }
    HingeJoint {
      jointParameters HingeJointParameters {
        position 0.03839999999999994
        axis 0 1 0
        anchor 0 0 1
      }
      device [
        RotationalMotor {
          name "motor_brazo_1"
          minPosition -1.5708
          maxPosition 1.5708
        }
        PositionSensor {
          name "sensor_brazo_1"
        }
      ]
      endPoint Solid {
        translation -0.03839056351176023 0 0.0007371894074863494
        rotation 0.9996314745551739 0.019195212577732414 -0.019195283085814783 1.5711685933584174
        children [
          CadShape {
            url [
              "/home/andres/programacion/brazo_robotico/worlds/brazo-1.obj"
            ]
          }
          HingeJoint {
            jointParameters HingeJointParameters {
              position -1.4880000000000053
              axis 0 0 1
              anchor 5.38 7.09 0.32
            }
            device [
              RotationalMotor {
                name "motor_brazo2_1"
                minPosition -1.6
                maxPosition 1.6
              }
              PositionSensor {
                name "sensor_brazo2_1"
              }
            ]
          }
        ]
        name "brazo"
      }
    }
  ]
  name "robot_brazo_1"
  controller "robot_brazo"
}
