#VRML_SIM R2025a utf8

EXTERNPROTO "https://raw.githubusercontent.com/cyberbotics/webots/R2025a/projects/objects/backgrounds/protos/TexturedBackground.proto"
EXTERNPROTO "https://raw.githubusercontent.com/cyberbotics/webots/R2025a/projects/objects/backgrounds/protos/TexturedBackgroundLight.proto"
EXTERNPROTO "https://raw.githubusercontent.com/cyberbotics/webots/R2025a/projects/objects/floors/protos/RectangleArena.proto"

WorldInfo {
}
Viewpoint {
  orientation 0.061210627032121136 -0.005948399257293949 0.9981071463949199 2.9482071102135214
  position 23.63197336501557 -2.5160659240930974 3.415674725285101
}
TexturedBackground {
}
TexturedBackgroundLight {
}
RectangleArena {
  translation 0.21 0 0
  floorSize 7 8
}
DEF ROBOT1 Robot {
  translation 0.7 1.3 -0.07
  children [
    DEF BASE Solid {
      rotation 1 0 0 1.5708
      children [
        CadShape {
          url [
            "/home/andres/programacion/brazo_robotico/worlds/base.obj"
          ]
        }
      ]
      name "base"
    }
    HingeJoint {
      jointParameters HingeJointParameters {
        position 0.03839999999999994
        axis 0 1 0
        anchor 0 0 1
      }
      device [
        RotationalMotor {
          name "motor_brazo_1"
          minPosition -1.5708
          maxPosition 1.5708
        }
        PositionSensor {
          name "sensor_brazo_1"
        }
      ]
      endPoint Solid {
        translation -0.03839056351176023 0 0.0007371894074863494
        rotation 0.9996314745551739 0.019195212577732414 -0.019195283085814783 1.5711685933584174
        children [
          CadShape {
            url [
              "/home/andres/programacion/brazo_robotico/worlds/brazo-1.obj"
            ]
          }
          HingeJoint {
            jointParameters HingeJointParameters {
              position -1.4880000000000053
              axis 0 0 1
              anchor 5.38 7.09 0.32
            }
            device [
              RotationalMotor {
                name "motor_brazo2_1"
                minPosition -1.6
                maxPosition 1.6
              }
              PositionSensor {
                name "sensor_brazo2_1"
              }
            ]
            endPoint Solid {
              rotation 0 1 0 0.523599
              children [
                HingeJoint {
                  jointParameters HingeJointParameters {
                    position -0.43199999999999994
                    axis 0 1 0
                    anchor 0 0 1
                  }
                  device [
                    RotationalMotor {
                      name "motor_brazo_3"
                      minPosition -1.5708
                      maxPosition 1.5708
                    }
                    PositionSensor {
                      name "sensor_brazo_3"
                    }
                  ]
                  endPoint Solid {
                    translation 0.41868789897527975 0 0.09186980930503841
                    rotation 0.9550733911475494 -0.20956442313357965 0.20956519290810183 1.6167509088783167
                    children [
                      CadShape {
                        url [
                          "/home/andres/programacion/brazo_robotico/worlds/brazo-1.obj"
                        ]
                      }
                      HingeJoint {
                        jointParameters HingeJointParameters {
                          position -1.4880000000000053
                          axis 0 0 1
                          anchor 5.38 7.09 0.32
                        }
                        device [
                          RotationalMotor {
                            name "motor_brazo2_3"
                            minPosition -1.6
                            maxPosition 1.6
                          }
                          PositionSensor {
                            name "sensor_brazo2_3"
                          }
                        ]
                      }
                    ]
                    name "brazo2"
                  }
                }
              ]
              name "brazo_extension"
            }
          }
        ]
        name "brazo"
      }
    }
  ]
  name "robot_brazo_1"
  controller "robot_brazo"
}
