#VRML_SIM R2025a utf8

EXTERNPROTO "https://raw.githubusercontent.com/cyberbotics/webots/R2025a/projects/objects/backgrounds/protos/TexturedBackground.proto"
EXTERNPROTO "https://raw.githubusercontent.com/cyberbotics/webots/R2025a/projects/objects/backgrounds/protos/TexturedBackgroundLight.proto"
EXTERNPROTO "https://raw.githubusercontent.com/cyberbotics/webots/R2025a/projects/objects/floors/protos/RectangleArena.proto"

WorldInfo {
}
Viewpoint {
  orientation 0.214789406505009 0.3682583171357625 -0.9045724529928835 1.1455246673745378
  position -8.635512872013816 20.89242622285093 20.946389949143956
}
TexturedBackground {
}
TexturedBackgroundLight {
}
RectangleArena {
  translation 0.21 0 0
  floorSize 26 26
}
DEF ROBOT1 Robot {
  children [
    DEF BASE Solid {
      children [
        Pose {
          rotation 1 0 0 1.57079632679
          children [
            CadShape {
              url [
                "../brazo-robotico/base.obj"
              ]
            }
          ]
        }
      ]
      name "base"
    }
    HingeJoint {
      jointParameters HingeJointParameters {
        position -2.0607999999999946
        axis 0 0 1
        anchor 0.024 -0.303 1.342
      }
      device [
        RotationalMotor {
          name "motor_base"
        }
        PositionSensor {
          name "sensor_base"
        }
      ]
      endPoint DEF BRAZO1 Solid {
        translation 0.30264143145910444 -0.42442467901716374 0.7080000000000007
        rotation 0 0 -1 2.0607999999999946
        children [
          Pose {
            rotation 1 0 0 1.57079632679
            children [
              CadShape {
                url [
                  "../brazo-robotico/brazo-1.obj"
                ]
              }
            ]
          }
          HingeJoint {
            jointParameters HingeJointParameters {
              position 1.0176000000000027
              axis 0 -1 0
              anchor 0.025 -0.284 5.498
            }
            device [
              RotationalMotor {
                name "motor_brazo_1"
                minPosition -0.5532
                maxPosition 2.5884
              }
              PositionSensor {
                name "sensor_brazo_1"
              }
            ]
            endPoint DEF BRAZO2 Solid {
              translation -0.149521 -0.580897 4.11777
              rotation -0.11772605004518573 -0.017109597230373374 -0.9928987052178951 3.08733965035168
              children [
                Pose {
                  rotation 1 0 0 1.57079632679
                  children [
                    CadShape {
                      url [
                        "../brazo-robotico/brazo-1.obj"
                      ]
                    }
                  ]
                }
                HingeJoint {
                    jointParameters HingeJointParameters {
                      axis 0 -1 0
                      anchor 0.025 -0.284 5.498
                    }
                    device [
                      RotationalMotor {
                        name "motor_brazo_2"
                      minPosition -1.5708
                      maxPosition 1.5708
                    }
                    PositionSensor {
                      name "sensor_brazo_2"
                    }
                  ]
                  endPoint DEF BRAZO3 Solid {
                    translation -0.07 0.0425758 4.05526
                    rotation 0 1 0 0
                    children [
                      Pose {
                        rotation 1 0 0 1.57079632679
                        children [
                          CadShape {
                            url [
                              "../brazo-robotico/brazo-1.obj"
                            ]
                          }
                        ]
                      }
                      HingeJoint {
                        jointParameters HingeJointParameters {
                          axis 0 -1 0
                          anchor 0.025 -0.284 5.498
                        }
                        device [
                          RotationalMotor {
                            name "motor_brazo_3"
                            minPosition -1.5708
                            maxPosition 1.5708
                          }
                          PositionSensor {
                            name "sensor_brazo_3"
                          }
                        ]
                        endPoint DEF GARRA Solid {
                          translation 0.005058 -0.0970561 4.12409
                          rotation 0 1 0 0
                          children [
                            Pose {
                              rotation 1 0 0 1.57079632679
                              children [
                                CadShape {
                                  url [
                                    "../brazo-robotico/garra.obj"
                                  ]
                                }
                              ]
                            }
                            DEF PUNTO_AGARRE Connector {
                              translation 0 -0.264 3
                              name "conector_garra"
                              boundingObject Sphere {
                                radius 0.001
                              }
                              distanceTolerance 50
                              axisTolerance 3.14159
                            }
                            HingeJoint {
                              jointParameters HingeJointParameters {
                                position -0.3680000000000001
                                axis 0 1 0
                                anchor -0.442 -0.264 3.249
                              }
                              device [
                                RotationalMotor {
                                  name "motor_garra_izq"
                                }
                                PositionSensor {
                                  name "sensor_garra_izq"
                                }
                              ]
                              endPoint Solid {
                                translation -0.442 -0.264 3.249
                                rotation 0 -1 0 0.3680000000000001
                                name "dedo_izq"
                                boundingObject Pose {
                                  translation 0 0 1.3
                                  children [
                                    Shape {
                                      geometry Box {
                                        size 0.2 0.2 2.6
                                      }
                                    }
                                  ]
                                }
                              }
                            }
                            HingeJoint {
                              jointParameters HingeJointParameters {
                                position -0.3680000000000001
                                axis 0 -1 0
                                anchor 0.467 -0.264 3.249
                              }
                              device [
                                RotationalMotor {
                                  name "motor_garra_der"
                                }
                                PositionSensor {
                                  name "sensor_garra_der"
                                }
                              ]
                              endPoint Solid {
                                translation 0.467 -0.264 3.249
                                rotation 0 1 0 0.3680000000000001
                                name "dedo_der"
                                boundingObject Pose {
                                  translation 0 0 1.3
                                  children [
                                    Shape {
                                      geometry Box {
                                        size 0.2 0.2 2.6
                                      }
                                    }
                                  ]
                                }
                              }
                            }
                          ]
                          name "garra"
                          boundingObject Pose {
                            translation 0 -0.264 1.5
                            children [
                              Shape {
                                geometry Box {
                                  size 1.1 0.4 3
                                }
                              }
                            ]
                          }
                        }
                      }
                    ]
                    name "brazo_3"
                    boundingObject Pose {
                      translation 0 0 2.7
                      children [
                        Shape {
                          geometry Cylinder {
                            height 5
                            radius 0.25
                          }
                        }
                      ]
                    }
                  }
                }
              ]
              name "brazo_2"
              boundingObject Pose {
                translation 0 0 2.7
                children [
                  Shape {
                    geometry Cylinder {
                      height 5
                      radius 0.25
                    }
                  }
                ]
              }
            }
          }
        ]
        name "brazo_1"
        boundingObject Pose {
          translation 0 0 2.7
          children [
            Shape {
              geometry Cylinder {
                height 5
                radius 0.25
              }
            }
          ]
        }
      }
    }
  ]
  name "robot_brazo_1"
  controller "robot_brazo"
  supervisor TRUE
}
DEF CAJA_ROJA Robot {
  translation 7.752190905521375e-16 5 0.29999960760056055
  rotation 0.025338894126261644 -0.8615224002919868 0.5070868705060224 7.30249591197799e-17
  children [
    Connector {
      name "conector_caja"
      boundingObject Sphere {
        radius 0.001
      }
      distanceTolerance 50
      axisTolerance 3.14159
    }
    Shape {
      appearance PBRAppearance {
        baseColor 0.8 0.2 0.2
        roughness 0.5
        metalness 0
      }
      geometry Box {
        size 0.6 0.6 0.6
      }
    }
  ]
  name "caja_roja"
  boundingObject Box {
    size 0.6 0.6 0.6
  }
  physics Physics {
    density -1
    mass 0.001
  }
  controller "<none>"
  linearVelocity -4.8775180533263716e-17 -9.507403294322056e-17 -4.379219209482699e-12
  angularVelocity 2.891205793294678e-16 -1.1564823173178715e-16 -3.7289839659410946e-18
}
DEF CILINDRO_AZUL Robot {
  translation 3 4 0.3999996076005606
  rotation 0.006445876253402873 0.011489899244392664 0.9999132126813205 6.434235471866164e-16
  children [
    Connector {
      name "conector_cilindro"
      boundingObject Sphere {
        radius 0.001
      }
      distanceTolerance 50
      axisTolerance 3.14159
    }
    Shape {
      appearance PBRAppearance {
        baseColor 0.1 0.3 0.9
        roughness 0.4
        metalness 0.1
      }
      geometry Cylinder {
        height 0.8
        radius 0.35
      }
    }
  ]
  name "cilindro_azul"
  boundingObject Cylinder {
    height 0.8
    radius 0.35
  }
  physics Physics {
    density -1
    mass 0.001
  }
  controller "<none>"
  linearVelocity -5.99407878624597e-17 1.0746810025370762e-16 -4.3791636983314675e-12
  angularVelocity -2.472157815352449e-16 -1.0626149070764201e-16 3.561830968301087e-17
}
DEF ESFERA_VERDE Robot {
  translation -3 4 0.39999843040224226
  children [
    Connector {
      name "conector_esfera"
      boundingObject Sphere {
        radius 0.001
      }
      distanceTolerance 50
      axisTolerance 3.14159
    }
    Shape {
      appearance PBRAppearance {
        baseColor 0.1 0.8 0.2
        roughness 0.6
        metalness 0
      }
      geometry Sphere {
        radius 0.4
      }
    }
  ]
  name "esfera_verde"
  boundingObject Sphere {
    radius 0.4
  }
  physics Physics {
    density -1
    mass 0.001
  }
  controller "<none>"
  linearVelocity 0 0 -1.751754297174557e-11
}
DEF CUBO_AMARILLO Robot {
  translation 3.12240511361526e-17 7 0.34999960760056054
  rotation -0.5263027510170556 -0.842084401627292 0.1178951856857815 5.1660636856640113e-17
  children [
    Connector {
      name "conector_cubo_am"
      boundingObject Sphere {
        radius 0.001
      }
      distanceTolerance 50
      axisTolerance 3.14159
    }
    Shape {
      appearance PBRAppearance {
        baseColor 0.95 0.85 0.1
        roughness 0.5
        metalness 0
      }
      geometry Box {
        size 0.7 0.7 0.7
      }
    }
  ]
  name "cubo_amarillo"
  boundingObject Box {
    size 0.7 0.7 0.7
  }
  physics Physics {
    density -1
    mass 0.001
  }
  controller "<none>"
  linearVelocity -3.4596912650731966e-17 -3.152754857822533e-17 -4.379219209482699e-12
  angularVelocity 4.248302390147283e-17 -8.496604780294566e-17 -2.0414909706837402e-17
}
DEF CUBO_NARANJA Robot {
  translation -4 7 0.24999960760056059
  rotation 0.19619975287739344 -0.4656474134955129 -0.8629473583456808 4.5777731079366185e-17
  children [
    Connector {
      name "conector_cubo_na"
      boundingObject Sphere {
        radius 0.001
      }
      distanceTolerance 50
      axisTolerance 3.14159
    }
    Shape {
      appearance PBRAppearance {
        baseColor 0.95 0.5 0.05
        roughness 0.3
        metalness 0.2
      }
      geometry Box {
        size 0.5 0.8 0.5
      }
    }
  ]
  name "cubo_naranja"
  boundingObject Box {
    size 0.5 0.8 0.5
  }
  physics Physics {
    density -1
    mass 0.001
  }
  controller "<none>"
  linearVelocity 4.739829903059906e-17 -5.947373344163632e-17 -4.379441254087624e-12
  angularVelocity 9.355812005268174e-17 2.498001805406602e-16 9.778070113597256e-18
}
Solid {
  translation 8 0 0.15
  children [
    Shape {
      appearance PBRAppearance {
        baseColor 0.25 0.28 0.32
        roughness 0.8
        metalness 0.6
      }
      geometry Box {
        size 4 4 0.3
      }
    }
  ]
  name "tanque_piso"
  boundingObject Box {
    size 4 4 0.3
  }
  locked TRUE
}
Solid {
  translation 8 2.1 1.3
  children [
    Shape {
      appearance PBRAppearance {
        baseColor 0.25 0.28 0.32
        roughness 0.8
        metalness 0.6
      }
      geometry Box {
        size 4 0.2 2.6
      }
    }
  ]
  name "tanque_pared_front"
  boundingObject Box {
    size 4 0.2 2.6
  }
  locked TRUE
}
Solid {
  translation 8 -2.1 1.3
  children [
    Shape {
      appearance PBRAppearance {
        baseColor 0.25 0.28 0.32
        roughness 0.8
        metalness 0.6
      }
      geometry Box {
        size 4 0.2 2.6
      }
    }
  ]
  name "tanque_pared_back"
  boundingObject Box {
    size 4 0.2 2.6
  }
  locked TRUE
}
Solid {
  translation 6.1 0 1.3
  children [
    Shape {
      appearance PBRAppearance {
        baseColor 0.25 0.28 0.32
        roughness 0.8
        metalness 0.6
      }
      geometry Box {
        size 0.2 4.4 2.6
      }
    }
  ]
  name "tanque_pared_izq"
  boundingObject Box {
    size 0.2 4.4 2.6
  }
  locked TRUE
}
Solid {
  translation 9.9 0 1.3
  children [
    Shape {
      appearance PBRAppearance {
        baseColor 0.25 0.28 0.32
        roughness 0.8
        metalness 0.6
      }
      geometry Box {
        size 0.2 4.4 2.6
      }
    }
  ]
  name "tanque_pared_der"
  boundingObject Box {
    size 0.2 4.4 2.6
  }
  locked TRUE
}
